[2025-05-01T08:16:25.111+0000] {local_task_job_runner.py:123} INFO - ::group::Pre task execution logs
[2025-05-01T08:16:25.118+0000] {taskinstance.py:2612} INFO - Dependencies all met for dep_context=non-requeueable deps ti=<TaskInstance: BuildELT_dbt.dbt_run manual__2025-05-01T00:00:00+00:00 [queued]>
[2025-05-01T08:16:25.122+0000] {taskinstance.py:2612} INFO - Dependencies all met for dep_context=requeueable deps ti=<TaskInstance: BuildELT_dbt.dbt_run manual__2025-05-01T00:00:00+00:00 [queued]>
[2025-05-01T08:16:25.123+0000] {taskinstance.py:2865} INFO - Starting attempt 1 of 1
[2025-05-01T08:16:25.127+0000] {taskinstance.py:2888} INFO - Executing <Task(BashOperator): dbt_run> on 2025-05-01 00:00:00+00:00
[2025-05-01T08:16:25.133+0000] {standard_task_runner.py:104} INFO - Running: ['***', 'tasks', 'run', 'BuildELT_dbt', 'dbt_run', 'manual__2025-05-01T00:00:00+00:00', '--job-id', '136', '--raw', '--subdir', 'DAGS_FOLDER/elt_with_dbt.py', '--cfg-path', '/tmp/tmp4_zanrv9']
[2025-05-01T08:16:25.135+0000] {standard_task_runner.py:105} INFO - Job 136: Subtask dbt_run
[2025-05-01T08:16:25.135+0000] {logging_mixin.py:190} WARNING - /home/***/.local/lib/python3.12/site-packages/***/task/task_runner/standard_task_runner.py:70 DeprecationWarning: This process (pid=4459) is multi-threaded, use of fork() may lead to deadlocks in the child.
[2025-05-01T08:16:25.137+0000] {standard_task_runner.py:72} INFO - Started process 4460 to run task
[2025-05-01T08:16:25.160+0000] {task_command.py:467} INFO - Running <TaskInstance: BuildELT_dbt.dbt_run manual__2025-05-01T00:00:00+00:00 [running]> on host 50fb0a9bb8ff
[2025-05-01T08:16:25.190+0000] {taskinstance.py:3131} INFO - Exporting env vars: AIRFLOW_CTX_DAG_OWNER='***' AIRFLOW_CTX_DAG_ID='BuildELT_dbt' AIRFLOW_CTX_TASK_ID='dbt_run' AIRFLOW_CTX_EXECUTION_DATE='2025-05-01T00:00:00+00:00' AIRFLOW_CTX_TRY_NUMBER='1' AIRFLOW_CTX_DAG_RUN_ID='manual__2025-05-01T00:00:00+00:00'
[2025-05-01T08:16:25.191+0000] {taskinstance.py:731} INFO - ::endgroup::
[2025-05-01T08:16:25.201+0000] {subprocess.py:63} INFO - Tmp dir root location: /tmp
[2025-05-01T08:16:25.201+0000] {subprocess.py:75} INFO - Running command: ['/usr/bin/bash', '-c', '/home/***/.local/bin/dbt run --profiles-dir /opt/***/project_dbt --project-dir /opt/***/project_dbt']
[2025-05-01T08:16:25.205+0000] {subprocess.py:86} INFO - Output:
[2025-05-01T08:16:26.157+0000] {subprocess.py:93} INFO - [0m08:16:26  Running with dbt=1.9.0-b4
[2025-05-01T08:16:26.647+0000] {subprocess.py:93} INFO - [0m08:16:26  Registered adapter: snowflake=1.8.0
[2025-05-01T08:16:26.888+0000] {subprocess.py:93} INFO - [0m08:16:26  Found 6 models, 60 data tests, 2 snapshots, 2 sources, 725 macros
[2025-05-01T08:16:26.890+0000] {subprocess.py:93} INFO - [0m08:16:26
[2025-05-01T08:16:26.890+0000] {subprocess.py:93} INFO - [0m08:16:26  Concurrency: 1 threads (target='dev')
[2025-05-01T08:16:26.890+0000] {subprocess.py:93} INFO - [0m08:16:26
[2025-05-01T08:16:32.359+0000] {subprocess.py:93} INFO - [0m08:16:32  1 of 4 START sql table model analytics.average_sj_weather ...................... [RUN]
[2025-05-01T08:16:34.177+0000] {subprocess.py:93} INFO - [0m08:16:34  1 of 4 OK created sql table model analytics.average_sj_weather ................. [[32mSUCCESS 1[0m in 1.81s]
[2025-05-01T08:16:34.181+0000] {subprocess.py:93} INFO - [0m08:16:34  2 of 4 START sql table model analytics.filtered_sj_weather ..................... [RUN]
[2025-05-01T08:16:36.117+0000] {subprocess.py:93} INFO - [0m08:16:36  2 of 4 OK created sql table model analytics.filtered_sj_weather ................ [[32mSUCCESS 1[0m in 1.93s]
[2025-05-01T08:16:36.119+0000] {subprocess.py:93} INFO - [0m08:16:36  3 of 4 START sql table model analytics.average_zipcode_data .................... [RUN]
[2025-05-01T08:16:37.853+0000] {subprocess.py:93} INFO - [0m08:16:37  3 of 4 OK created sql table model analytics.average_zipcode_data ............... [[32mSUCCESS 1[0m in 1.73s]
[2025-05-01T08:16:37.857+0000] {subprocess.py:93} INFO - [0m08:16:37  4 of 4 START sql table model analytics.filtered_zipcode_data ................... [RUN]
[2025-05-01T08:16:40.397+0000] {subprocess.py:93} INFO - [0m08:16:40  4 of 4 OK created sql table model analytics.filtered_zipcode_data .............. [[32mSUCCESS 1[0m in 2.53s]
[2025-05-01T08:16:40.404+0000] {subprocess.py:93} INFO - [0m08:16:40
[2025-05-01T08:16:40.405+0000] {subprocess.py:93} INFO - [0m08:16:40  Finished running 4 table models in 0 hours 0 minutes and 13.51 seconds (13.51s).
[2025-05-01T08:16:40.591+0000] {subprocess.py:93} INFO - [0m08:16:40
[2025-05-01T08:16:40.592+0000] {subprocess.py:93} INFO - [0m08:16:40  [32mCompleted successfully[0m
[2025-05-01T08:16:40.592+0000] {subprocess.py:93} INFO - [0m08:16:40
[2025-05-01T08:16:40.593+0000] {subprocess.py:93} INFO - [0m08:16:40  Done. PASS=4 WARN=0 ERROR=0 SKIP=0 TOTAL=4
[2025-05-01T08:16:41.340+0000] {subprocess.py:97} INFO - Command exited with return code 0
[2025-05-01T08:16:41.367+0000] {taskinstance.py:3310} ERROR - Task failed with exception
Traceback (most recent call last):
  File "/home/airflow/.local/lib/python3.12/site-packages/sqlalchemy/engine/base.py", line 1910, in _execute_context
    self.dialect.do_execute(
  File "/home/airflow/.local/lib/python3.12/site-packages/sqlalchemy/engine/default.py", line 736, in do_execute
    cursor.execute(statement, parameters)
psycopg2.errors.UniqueViolation: duplicate key value violates unique constraint "xcom_pkey"
DETAIL:  Key (dag_run_id, task_id, map_index, key)=(68, dbt_run, -1, return_value) already exists.


The above exception was the direct cause of the following exception:

Traceback (most recent call last):
  File "/home/airflow/.local/lib/python3.12/site-packages/airflow/models/taskinstance.py", line 789, in _execute_task
    task_instance.xcom_push(key=XCOM_RETURN_KEY, value=xcom_value, session=session_or_null)
  File "/home/airflow/.local/lib/python3.12/site-packages/airflow/utils/session.py", line 94, in wrapper
    return func(*args, **kwargs)
           ^^^^^^^^^^^^^^^^^^^^^
  File "/home/airflow/.local/lib/python3.12/site-packages/airflow/models/taskinstance.py", line 3638, in xcom_push
    XCom.set(
  File "/home/airflow/.local/lib/python3.12/site-packages/airflow/api_internal/internal_api_call.py", line 139, in wrapper
    return func(*args, **kwargs)
           ^^^^^^^^^^^^^^^^^^^^^
  File "/home/airflow/.local/lib/python3.12/site-packages/airflow/utils/session.py", line 94, in wrapper
    return func(*args, **kwargs)
           ^^^^^^^^^^^^^^^^^^^^^
  File "/home/airflow/.local/lib/python3.12/site-packages/airflow/models/xcom.py", line 278, in set
    session.flush()
  File "/home/airflow/.local/lib/python3.12/site-packages/sqlalchemy/orm/session.py", line 3449, in flush
    self._flush(objects)
  File "/home/airflow/.local/lib/python3.12/site-packages/sqlalchemy/orm/session.py", line 3588, in _flush
    with util.safe_reraise():
  File "/home/airflow/.local/lib/python3.12/site-packages/sqlalchemy/util/langhelpers.py", line 70, in __exit__
    compat.raise_(
  File "/home/airflow/.local/lib/python3.12/site-packages/sqlalchemy/util/compat.py", line 211, in raise_
    raise exception
  File "/home/airflow/.local/lib/python3.12/site-packages/sqlalchemy/orm/session.py", line 3549, in _flush
    flush_context.execute()
  File "/home/airflow/.local/lib/python3.12/site-packages/sqlalchemy/orm/unitofwork.py", line 456, in execute
    rec.execute(self)
  File "/home/airflow/.local/lib/python3.12/site-packages/sqlalchemy/orm/unitofwork.py", line 630, in execute
    util.preloaded.orm_persistence.save_obj(
  File "/home/airflow/.local/lib/python3.12/site-packages/sqlalchemy/orm/persistence.py", line 245, in save_obj
    _emit_insert_statements(
  File "/home/airflow/.local/lib/python3.12/site-packages/sqlalchemy/orm/persistence.py", line 1097, in _emit_insert_statements
    c = connection._execute_20(
        ^^^^^^^^^^^^^^^^^^^^^^^
  File "/home/airflow/.local/lib/python3.12/site-packages/sqlalchemy/engine/base.py", line 1710, in _execute_20
    return meth(self, args_10style, kwargs_10style, execution_options)
           ^^^^^^^^^^^^^^^^^^^^^^^^^^^^^^^^^^^^^^^^^^^^^^^^^^^^^^^^^^^
  File "/home/airflow/.local/lib/python3.12/site-packages/sqlalchemy/sql/elements.py", line 334, in _execute_on_connection
    return connection._execute_clauseelement(
           ^^^^^^^^^^^^^^^^^^^^^^^^^^^^^^^^^^
  File "/home/airflow/.local/lib/python3.12/site-packages/sqlalchemy/engine/base.py", line 1577, in _execute_clauseelement
    ret = self._execute_context(
          ^^^^^^^^^^^^^^^^^^^^^^
  File "/home/airflow/.local/lib/python3.12/site-packages/sqlalchemy/engine/base.py", line 1953, in _execute_context
    self._handle_dbapi_exception(
  File "/home/airflow/.local/lib/python3.12/site-packages/sqlalchemy/engine/base.py", line 2134, in _handle_dbapi_exception
    util.raise_(
  File "/home/airflow/.local/lib/python3.12/site-packages/sqlalchemy/util/compat.py", line 211, in raise_
    raise exception
  File "/home/airflow/.local/lib/python3.12/site-packages/sqlalchemy/engine/base.py", line 1910, in _execute_context
    self.dialect.do_execute(
  File "/home/airflow/.local/lib/python3.12/site-packages/sqlalchemy/engine/default.py", line 736, in do_execute
    cursor.execute(statement, parameters)
sqlalchemy.exc.IntegrityError: (psycopg2.errors.UniqueViolation) duplicate key value violates unique constraint "xcom_pkey"
DETAIL:  Key (dag_run_id, task_id, map_index, key)=(68, dbt_run, -1, return_value) already exists.

[SQL: INSERT INTO xcom (dag_run_id, task_id, map_index, key, dag_id, run_id, value, timestamp) VALUES (%(dag_run_id)s, %(task_id)s, %(map_index)s, %(key)s, %(dag_id)s, %(run_id)s, %(value)s, %(timestamp)s)]
[parameters: {'dag_run_id': 68, 'task_id': 'dbt_run', 'map_index': -1, 'key': 'return_value', 'dag_id': 'BuildELT_dbt', 'run_id': 'manual__2025-05-01T00:00:00+00:00', 'value': <psycopg2.extensions.Binary object at 0xffff97ec6520>, 'timestamp': datetime.datetime(2025, 5, 1, 8, 16, 41, 365070, tzinfo=Timezone('UTC'))}]
(Background on this error at: https://sqlalche.me/e/14/gkpj)
[2025-05-01T08:16:41.385+0000] {taskinstance.py:1225} INFO - Marking task as FAILED. dag_id=BuildELT_dbt, task_id=dbt_run, run_id=manual__2025-05-01T00:00:00+00:00, execution_date=20250501T000000, start_date=20250501T081625, end_date=20250501T081641
[2025-05-01T08:16:41.393+0000] {taskinstance.py:340} INFO - ::group::Post task execution logs
[2025-05-01T08:16:41.394+0000] {standard_task_runner.py:124} ERROR - Failed to execute job 136 for task dbt_run ((psycopg2.errors.UniqueViolation) duplicate key value violates unique constraint "xcom_pkey"
DETAIL:  Key (dag_run_id, task_id, map_index, key)=(68, dbt_run, -1, return_value) already exists.

[SQL: INSERT INTO xcom (dag_run_id, task_id, map_index, key, dag_id, run_id, value, timestamp) VALUES (%(dag_run_id)s, %(task_id)s, %(map_index)s, %(key)s, %(dag_id)s, %(run_id)s, %(value)s, %(timestamp)s)]
[parameters: {'dag_run_id': 68, 'task_id': 'dbt_run', 'map_index': -1, 'key': 'return_value', 'dag_id': 'BuildELT_dbt', 'run_id': 'manual__2025-05-01T00:00:00+00:00', 'value': <psycopg2.extensions.Binary object at 0xffff97ec6520>, 'timestamp': datetime.datetime(2025, 5, 1, 8, 16, 41, 365070, tzinfo=Timezone('UTC'))}]
(Background on this error at: https://sqlalche.me/e/14/gkpj); 4460)
Traceback (most recent call last):
  File "/home/airflow/.local/lib/python3.12/site-packages/sqlalchemy/engine/base.py", line 1910, in _execute_context
    self.dialect.do_execute(
  File "/home/airflow/.local/lib/python3.12/site-packages/sqlalchemy/engine/default.py", line 736, in do_execute
    cursor.execute(statement, parameters)
psycopg2.errors.UniqueViolation: duplicate key value violates unique constraint "xcom_pkey"
DETAIL:  Key (dag_run_id, task_id, map_index, key)=(68, dbt_run, -1, return_value) already exists.


The above exception was the direct cause of the following exception:

Traceback (most recent call last):
  File "/home/airflow/.local/lib/python3.12/site-packages/airflow/task/task_runner/standard_task_runner.py", line 117, in _start_by_fork
    ret = args.func(args, dag=self.dag)
          ^^^^^^^^^^^^^^^^^^^^^^^^^^^^^
  File "/home/airflow/.local/lib/python3.12/site-packages/airflow/cli/cli_config.py", line 49, in command
    return func(*args, **kwargs)
           ^^^^^^^^^^^^^^^^^^^^^
  File "/home/airflow/.local/lib/python3.12/site-packages/airflow/utils/cli.py", line 115, in wrapper
    return f(*args, **kwargs)
           ^^^^^^^^^^^^^^^^^^
  File "/home/airflow/.local/lib/python3.12/site-packages/airflow/cli/commands/task_command.py", line 483, in task_run
    task_return_code = _run_task_by_selected_method(args, _dag, ti)
                       ^^^^^^^^^^^^^^^^^^^^^^^^^^^^^^^^^^^^^^^^^^^^
  File "/home/airflow/.local/lib/python3.12/site-packages/airflow/cli/commands/task_command.py", line 256, in _run_task_by_selected_method
    return _run_raw_task(args, ti)
           ^^^^^^^^^^^^^^^^^^^^^^^
  File "/home/airflow/.local/lib/python3.12/site-packages/airflow/cli/commands/task_command.py", line 341, in _run_raw_task
    return ti._run_raw_task(
           ^^^^^^^^^^^^^^^^^
  File "/home/airflow/.local/lib/python3.12/site-packages/airflow/utils/session.py", line 97, in wrapper
    return func(*args, session=session, **kwargs)
           ^^^^^^^^^^^^^^^^^^^^^^^^^^^^^^^^^^^^^^
  File "/home/airflow/.local/lib/python3.12/site-packages/airflow/models/taskinstance.py", line 3004, in _run_raw_task
    return _run_raw_task(
           ^^^^^^^^^^^^^^
  File "/home/airflow/.local/lib/python3.12/site-packages/airflow/models/taskinstance.py", line 273, in _run_raw_task
    TaskInstance._execute_task_with_callbacks(
  File "/home/airflow/.local/lib/python3.12/site-packages/airflow/models/taskinstance.py", line 3158, in _execute_task_with_callbacks
    result = self._execute_task(context, task_orig)
             ^^^^^^^^^^^^^^^^^^^^^^^^^^^^^^^^^^^^^^
  File "/home/airflow/.local/lib/python3.12/site-packages/airflow/models/taskinstance.py", line 3182, in _execute_task
    return _execute_task(self, context, task_orig)
           ^^^^^^^^^^^^^^^^^^^^^^^^^^^^^^^^^^^^^^^
  File "/home/airflow/.local/lib/python3.12/site-packages/airflow/models/taskinstance.py", line 789, in _execute_task
    task_instance.xcom_push(key=XCOM_RETURN_KEY, value=xcom_value, session=session_or_null)
  File "/home/airflow/.local/lib/python3.12/site-packages/airflow/utils/session.py", line 94, in wrapper
    return func(*args, **kwargs)
           ^^^^^^^^^^^^^^^^^^^^^
  File "/home/airflow/.local/lib/python3.12/site-packages/airflow/models/taskinstance.py", line 3638, in xcom_push
    XCom.set(
  File "/home/airflow/.local/lib/python3.12/site-packages/airflow/api_internal/internal_api_call.py", line 139, in wrapper
    return func(*args, **kwargs)
           ^^^^^^^^^^^^^^^^^^^^^
  File "/home/airflow/.local/lib/python3.12/site-packages/airflow/utils/session.py", line 94, in wrapper
    return func(*args, **kwargs)
           ^^^^^^^^^^^^^^^^^^^^^
  File "/home/airflow/.local/lib/python3.12/site-packages/airflow/models/xcom.py", line 278, in set
    session.flush()
  File "/home/airflow/.local/lib/python3.12/site-packages/sqlalchemy/orm/session.py", line 3449, in flush
    self._flush(objects)
  File "/home/airflow/.local/lib/python3.12/site-packages/sqlalchemy/orm/session.py", line 3588, in _flush
    with util.safe_reraise():
  File "/home/airflow/.local/lib/python3.12/site-packages/sqlalchemy/util/langhelpers.py", line 70, in __exit__
    compat.raise_(
  File "/home/airflow/.local/lib/python3.12/site-packages/sqlalchemy/util/compat.py", line 211, in raise_
    raise exception
  File "/home/airflow/.local/lib/python3.12/site-packages/sqlalchemy/orm/session.py", line 3549, in _flush
    flush_context.execute()
  File "/home/airflow/.local/lib/python3.12/site-packages/sqlalchemy/orm/unitofwork.py", line 456, in execute
    rec.execute(self)
  File "/home/airflow/.local/lib/python3.12/site-packages/sqlalchemy/orm/unitofwork.py", line 630, in execute
    util.preloaded.orm_persistence.save_obj(
  File "/home/airflow/.local/lib/python3.12/site-packages/sqlalchemy/orm/persistence.py", line 245, in save_obj
    _emit_insert_statements(
  File "/home/airflow/.local/lib/python3.12/site-packages/sqlalchemy/orm/persistence.py", line 1097, in _emit_insert_statements
    c = connection._execute_20(
        ^^^^^^^^^^^^^^^^^^^^^^^
  File "/home/airflow/.local/lib/python3.12/site-packages/sqlalchemy/engine/base.py", line 1710, in _execute_20
    return meth(self, args_10style, kwargs_10style, execution_options)
           ^^^^^^^^^^^^^^^^^^^^^^^^^^^^^^^^^^^^^^^^^^^^^^^^^^^^^^^^^^^
  File "/home/airflow/.local/lib/python3.12/site-packages/sqlalchemy/sql/elements.py", line 334, in _execute_on_connection
    return connection._execute_clauseelement(
           ^^^^^^^^^^^^^^^^^^^^^^^^^^^^^^^^^^
  File "/home/airflow/.local/lib/python3.12/site-packages/sqlalchemy/engine/base.py", line 1577, in _execute_clauseelement
    ret = self._execute_context(
          ^^^^^^^^^^^^^^^^^^^^^^
  File "/home/airflow/.local/lib/python3.12/site-packages/sqlalchemy/engine/base.py", line 1953, in _execute_context
    self._handle_dbapi_exception(
  File "/home/airflow/.local/lib/python3.12/site-packages/sqlalchemy/engine/base.py", line 2134, in _handle_dbapi_exception
    util.raise_(
  File "/home/airflow/.local/lib/python3.12/site-packages/sqlalchemy/util/compat.py", line 211, in raise_
    raise exception
  File "/home/airflow/.local/lib/python3.12/site-packages/sqlalchemy/engine/base.py", line 1910, in _execute_context
    self.dialect.do_execute(
  File "/home/airflow/.local/lib/python3.12/site-packages/sqlalchemy/engine/default.py", line 736, in do_execute
    cursor.execute(statement, parameters)
sqlalchemy.exc.IntegrityError: (psycopg2.errors.UniqueViolation) duplicate key value violates unique constraint "xcom_pkey"
DETAIL:  Key (dag_run_id, task_id, map_index, key)=(68, dbt_run, -1, return_value) already exists.

[SQL: INSERT INTO xcom (dag_run_id, task_id, map_index, key, dag_id, run_id, value, timestamp) VALUES (%(dag_run_id)s, %(task_id)s, %(map_index)s, %(key)s, %(dag_id)s, %(run_id)s, %(value)s, %(timestamp)s)]
[parameters: {'dag_run_id': 68, 'task_id': 'dbt_run', 'map_index': -1, 'key': 'return_value', 'dag_id': 'BuildELT_dbt', 'run_id': 'manual__2025-05-01T00:00:00+00:00', 'value': <psycopg2.extensions.Binary object at 0xffff97ec6520>, 'timestamp': datetime.datetime(2025, 5, 1, 8, 16, 41, 365070, tzinfo=Timezone('UTC'))}]
(Background on this error at: https://sqlalche.me/e/14/gkpj)
[2025-05-01T08:16:41.423+0000] {local_task_job_runner.py:266} INFO - Task exited with return code 1
[2025-05-01T08:16:41.441+0000] {taskinstance.py:3900} INFO - 0 downstream tasks scheduled from follow-on schedule check
[2025-05-01T08:16:41.443+0000] {local_task_job_runner.py:245} INFO - ::endgroup::
