[2025-05-01T00:35:36.382+0000] {local_task_job_runner.py:123} INFO - ::group::Pre task execution logs
[2025-05-01T00:35:36.388+0000] {taskinstance.py:2612} INFO - Dependencies all met for dep_context=non-requeueable deps ti=<TaskInstance: weather_history_sanjose.load_weather_history scheduled__2025-04-30T00:00:00+00:00 [queued]>
[2025-05-01T00:35:36.392+0000] {taskinstance.py:2612} INFO - Dependencies all met for dep_context=requeueable deps ti=<TaskInstance: weather_history_sanjose.load_weather_history scheduled__2025-04-30T00:00:00+00:00 [queued]>
[2025-05-01T00:35:36.393+0000] {taskinstance.py:2865} INFO - Starting attempt 1 of 1
[2025-05-01T00:35:36.397+0000] {taskinstance.py:2888} INFO - Executing <Task(_PythonDecoratedOperator): load_weather_history> on 2025-04-30 00:00:00+00:00
[2025-05-01T00:35:36.400+0000] {logging_mixin.py:190} WARNING - /home/***/.local/lib/python3.12/site-packages/***/task/task_runner/standard_task_runner.py:70 DeprecationWarning: This process (pid=399) is multi-threaded, use of fork() may lead to deadlocks in the child.
[2025-05-01T00:35:36.401+0000] {standard_task_runner.py:72} INFO - Started process 406 to run task
[2025-05-01T00:35:36.401+0000] {standard_task_runner.py:104} INFO - Running: ['***', 'tasks', 'run', 'weather_history_sanjose', 'load_weather_history', 'scheduled__2025-04-30T00:00:00+00:00', '--job-id', '73', '--raw', '--subdir', 'DAGS_FOLDER/weather_history_sj.py', '--cfg-path', '/tmp/tmpsj6ykqtt']
[2025-05-01T00:35:36.402+0000] {standard_task_runner.py:105} INFO - Job 73: Subtask load_weather_history
[2025-05-01T00:35:36.417+0000] {task_command.py:467} INFO - Running <TaskInstance: weather_history_sanjose.load_weather_history scheduled__2025-04-30T00:00:00+00:00 [running]> on host a70fb8b05a55
[2025-05-01T00:35:36.471+0000] {taskinstance.py:3131} INFO - Exporting env vars: AIRFLOW_CTX_DAG_OWNER='***' AIRFLOW_CTX_DAG_ID='weather_history_sanjose' AIRFLOW_CTX_TASK_ID='load_weather_history' AIRFLOW_CTX_EXECUTION_DATE='2025-04-30T00:00:00+00:00' AIRFLOW_CTX_TRY_NUMBER='1' AIRFLOW_CTX_DAG_RUN_ID='scheduled__2025-04-30T00:00:00+00:00'
[2025-05-01T00:35:36.472+0000] {taskinstance.py:731} INFO - ::endgroup::
[2025-05-01T00:35:36.476+0000] {base.py:84} INFO - Retrieving connection 'snowflake_conn'
[2025-05-01T00:35:36.478+0000] {connection.py:413} INFO - Snowflake Connector for Python Version: 3.12.1, Python Version: 3.12.5, Platform: Linux-6.12.5-linuxkit-aarch64-with-glibc2.36
[2025-05-01T00:35:36.479+0000] {connection.py:1196} INFO - Connecting to GLOBAL Snowflake domain
[2025-05-01T00:35:36.479+0000] {connection.py:1277} INFO - This connection is in OCSP Fail Open Mode. TLS Certificates would be checked for validity and revocation status. Any other Certificate Revocation related exceptions or OCSP Responder failures would be disregarded in favor of connectivity.
[2025-05-01T00:35:37.966+0000] {cursor.py:1156} INFO - Number of results in first chunk: 1
[2025-05-01T00:35:38.289+0000] {cursor.py:1156} INFO - Number of results in first chunk: 1
[2025-05-01T00:47:59.580+0000] {local_task_job_runner.py:346} WARNING - State of this instance has been externally set to failed. Terminating instance.
[2025-05-01T00:47:59.585+0000] {local_task_job_runner.py:245} INFO - ::endgroup::
[2025-05-01T00:47:59.586+0000] {process_utils.py:132} INFO - Sending 15 to group 406. PIDs of all processes in the group: [406]
[2025-05-01T00:47:59.587+0000] {process_utils.py:87} INFO - Sending the signal 15 to group 406
[2025-05-01T00:47:59.588+0000] {taskinstance.py:3092} ERROR - Received SIGTERM. Terminating subprocesses.
[2025-05-01T00:47:59.626+0000] {taskinstance.py:340} INFO - ::group::Post task execution logs
[2025-05-01T00:47:59.646+0000] {process_utils.py:80} INFO - Process psutil.Process(pid=406, status='terminated', exitcode=0, started='00:35:36') (406) terminated with exit code 0
