[2025-05-01T07:34:52.029+0000] {local_task_job_runner.py:123} INFO - ::group::Pre task execution logs
[2025-05-01T07:34:52.048+0000] {taskinstance.py:2612} INFO - Dependencies all met for dep_context=non-requeueable deps ti=<TaskInstance: BuildELT_dbt.dbt_run manual__2025-04-30T00:00:00+00:00 [queued]>
[2025-05-01T07:34:52.054+0000] {taskinstance.py:2612} INFO - Dependencies all met for dep_context=requeueable deps ti=<TaskInstance: BuildELT_dbt.dbt_run manual__2025-04-30T00:00:00+00:00 [queued]>
[2025-05-01T07:34:52.055+0000] {taskinstance.py:2865} INFO - Starting attempt 2 of 2
[2025-05-01T07:34:52.066+0000] {taskinstance.py:2888} INFO - Executing <Task(BashOperator): dbt_run> on 2025-04-30 00:00:00+00:00
[2025-05-01T07:34:52.075+0000] {logging_mixin.py:190} WARNING - /home/***/.local/lib/python3.12/site-packages/***/task/task_runner/standard_task_runner.py:70 DeprecationWarning: This process (pid=1877) is multi-threaded, use of fork() may lead to deadlocks in the child.
[2025-05-01T07:34:52.073+0000] {standard_task_runner.py:104} INFO - Running: ['***', 'tasks', 'run', 'BuildELT_dbt', 'dbt_run', 'manual__2025-04-30T00:00:00+00:00', '--job-id', '113', '--raw', '--subdir', 'DAGS_FOLDER/elt_with_dbt.py', '--cfg-path', '/tmp/tmpkx26865n']
[2025-05-01T07:34:52.076+0000] {standard_task_runner.py:105} INFO - Job 113: Subtask dbt_run
[2025-05-01T07:34:52.076+0000] {standard_task_runner.py:72} INFO - Started process 1878 to run task
[2025-05-01T07:34:52.096+0000] {task_command.py:467} INFO - Running <TaskInstance: BuildELT_dbt.dbt_run manual__2025-04-30T00:00:00+00:00 [running]> on host 50fb0a9bb8ff
[2025-05-01T07:34:52.129+0000] {taskinstance.py:3131} INFO - Exporting env vars: AIRFLOW_CTX_DAG_OWNER='***' AIRFLOW_CTX_DAG_ID='BuildELT_dbt' AIRFLOW_CTX_TASK_ID='dbt_run' AIRFLOW_CTX_EXECUTION_DATE='2025-04-30T00:00:00+00:00' AIRFLOW_CTX_TRY_NUMBER='2' AIRFLOW_CTX_DAG_RUN_ID='manual__2025-04-30T00:00:00+00:00'
[2025-05-01T07:34:52.130+0000] {taskinstance.py:731} INFO - ::endgroup::
[2025-05-01T07:34:52.139+0000] {subprocess.py:63} INFO - Tmp dir root location: /tmp
[2025-05-01T07:34:52.140+0000] {subprocess.py:75} INFO - Running command: ['/usr/bin/bash', '-c', '/home/***/.local/bin/dbt run --profiles-dir /opt/***/project_dbt --project-dir /opt/***/project_dbt']
[2025-05-01T07:34:52.144+0000] {subprocess.py:86} INFO - Output:
[2025-05-01T07:34:53.198+0000] {subprocess.py:93} INFO - [0m07:34:53  Running with dbt=1.9.0-b4
[2025-05-01T07:34:53.708+0000] {subprocess.py:93} INFO - [0m07:34:53  Registered adapter: snowflake=1.8.0
[2025-05-01T07:34:53.946+0000] {subprocess.py:93} INFO - [0m07:34:53  Found 6 models, 2 snapshots, 60 data tests, 2 sources, 725 macros
[2025-05-01T07:34:53.947+0000] {subprocess.py:93} INFO - [0m07:34:53
[2025-05-01T07:34:53.948+0000] {subprocess.py:93} INFO - [0m07:34:53  Concurrency: 1 threads (target='dev')
[2025-05-01T07:34:53.948+0000] {subprocess.py:93} INFO - [0m07:34:53
[2025-05-01T07:34:58.253+0000] {subprocess.py:93} INFO - [0m07:34:58  1 of 4 START sql table model analytics.average_sj_weather ...................... [RUN]
[2025-05-01T07:35:01.312+0000] {subprocess.py:93} INFO - [0m07:35:01  1 of 4 OK created sql table model analytics.average_sj_weather ................. [[32mSUCCESS 1[0m in 3.05s]
[2025-05-01T07:35:01.316+0000] {subprocess.py:93} INFO - [0m07:35:01  2 of 4 START sql table model analytics.filtered_sj_weather ..................... [RUN]
[2025-05-01T07:35:02.185+0000] {local_task_job_runner.py:318} WARNING - Recorded pid 1920 does not match the current pid 1878
[2025-05-01T07:35:02.187+0000] {local_task_job_runner.py:218} WARNING - Heartbeat failed with Exception: PID of job runner does not match
[2025-05-01T07:35:02.800+0000] {subprocess.py:93} INFO - [0m07:35:02  2 of 4 OK created sql table model analytics.filtered_sj_weather ................ [[32mSUCCESS 1[0m in 1.48s]
[2025-05-01T07:35:02.803+0000] {subprocess.py:93} INFO - [0m07:35:02  3 of 4 START sql table model analytics.average_zipcode_data .................... [RUN]
[2025-05-01T07:35:04.298+0000] {subprocess.py:93} INFO - [0m07:35:04  3 of 4 OK created sql table model analytics.average_zipcode_data ............... [[32mSUCCESS 1[0m in 1.49s]
[2025-05-01T07:35:04.302+0000] {subprocess.py:93} INFO - [0m07:35:04  4 of 4 START sql table model analytics.filtered_zipcode_data ................... [RUN]
[2025-05-01T07:35:06.963+0000] {subprocess.py:93} INFO - [0m07:35:06  4 of 4 OK created sql table model analytics.filtered_zipcode_data .............. [[32mSUCCESS 1[0m in 2.66s]
[2025-05-01T07:35:06.971+0000] {subprocess.py:93} INFO - [0m07:35:06
[2025-05-01T07:35:06.972+0000] {subprocess.py:93} INFO - [0m07:35:06  Finished running 4 table models in 0 hours 0 minutes and 13.02 seconds (13.02s).
[2025-05-01T07:35:07.137+0000] {subprocess.py:93} INFO - [0m07:35:07
[2025-05-01T07:35:07.138+0000] {subprocess.py:93} INFO - [0m07:35:07  [32mCompleted successfully[0m
[2025-05-01T07:35:07.138+0000] {subprocess.py:93} INFO - [0m07:35:07
[2025-05-01T07:35:07.138+0000] {subprocess.py:93} INFO - [0m07:35:07  Done. PASS=4 WARN=0 ERROR=0 SKIP=0 TOTAL=4
[2025-05-01T07:35:07.260+0000] {local_task_job_runner.py:318} WARNING - Recorded pid 1920 does not match the current pid 1878
[2025-05-01T07:35:07.261+0000] {local_task_job_runner.py:218} WARNING - Heartbeat failed with Exception: PID of job runner does not match
[2025-05-01T07:35:07.851+0000] {subprocess.py:97} INFO - Command exited with return code 0
[2025-05-01T07:35:07.883+0000] {taskinstance.py:340} INFO - ::group::Post task execution logs
[2025-05-01T07:35:07.883+0000] {taskinstance.py:352} INFO - Marking task as SUCCESS. dag_id=BuildELT_dbt, task_id=dbt_run, run_id=manual__2025-04-30T00:00:00+00:00, execution_date=20250430T000000, start_date=20250501T073458, end_date=20250501T073507
[2025-05-01T07:35:07.891+0000] {standard_task_runner.py:124} ERROR - Failed to execute job 113 for task dbt_run ((psycopg2.errors.UniqueViolation) duplicate key value violates unique constraint "dag_run_dag_id_execution_date_key"
DETAIL:  Key (dag_id, execution_date)=(BuildELT_dbt, 2025-04-30 00:00:00+00) already exists.

[SQL: INSERT INTO dag_run (id, dag_id, queued_at, execution_date, start_date, end_date, state, run_id, creating_job_id, external_trigger, run_type, conf, data_interval_start, data_interval_end, last_scheduling_decision, dag_hash, log_template_id, updated_at, clear_number) VALUES (%(id)s, %(dag_id)s, %(queued_at)s, %(execution_date)s, %(start_date)s, %(end_date)s, %(state)s, %(run_id)s, %(creating_job_id)s, %(external_trigger)s, %(run_type)s, %(conf)s, %(data_interval_start)s, %(data_interval_end)s, %(last_scheduling_decision)s, %(dag_hash)s, %(log_template_id)s, %(updated_at)s, %(clear_number)s)]
[parameters: {'id': 52, 'dag_id': 'BuildELT_dbt', 'queued_at': datetime.datetime(2025, 5, 1, 7, 34, 51, 173886, tzinfo=Timezone('UTC')), 'execution_date': datetime.datetime(2025, 4, 30, 0, 0, tzinfo=Timezone('UTC')), 'start_date': datetime.datetime(2025, 5, 1, 7, 34, 51, 899713, tzinfo=Timezone('UTC')), 'end_date': None, 'state': 'running', 'run_id': 'manual__2025-04-30T00:00:00+00:00', 'creating_job_id': None, 'external_trigger': False, 'run_type': 'manual', 'conf': <psycopg2.extensions.Binary object at 0xffff97ec5ce0>, 'data_interval_start': datetime.datetime(2025, 4, 30, 0, 0, tzinfo=Timezone('UTC')), 'data_interval_end': datetime.datetime(2025, 4, 30, 0, 0, tzinfo=Timezone('UTC')), 'last_scheduling_decision': datetime.datetime(2025, 5, 1, 7, 34, 51, 939840, tzinfo=Timezone('UTC')), 'dag_hash': '5de38bd7dad17b8a325bb073f9b82c0c', 'log_template_id': 2, 'updated_at': datetime.datetime(2025, 5, 1, 7, 34, 51, 941816, tzinfo=Timezone('UTC')), 'clear_number': 1}]
(Background on this error at: https://sqlalche.me/e/14/gkpj); 1878)
Traceback (most recent call last):
  File "/home/airflow/.local/lib/python3.12/site-packages/sqlalchemy/engine/base.py", line 1910, in _execute_context
    self.dialect.do_execute(
  File "/home/airflow/.local/lib/python3.12/site-packages/sqlalchemy/engine/default.py", line 736, in do_execute
    cursor.execute(statement, parameters)
psycopg2.errors.UniqueViolation: duplicate key value violates unique constraint "dag_run_dag_id_execution_date_key"
DETAIL:  Key (dag_id, execution_date)=(BuildELT_dbt, 2025-04-30 00:00:00+00) already exists.


The above exception was the direct cause of the following exception:

Traceback (most recent call last):
  File "/home/airflow/.local/lib/python3.12/site-packages/airflow/task/task_runner/standard_task_runner.py", line 117, in _start_by_fork
    ret = args.func(args, dag=self.dag)
          ^^^^^^^^^^^^^^^^^^^^^^^^^^^^^
  File "/home/airflow/.local/lib/python3.12/site-packages/airflow/cli/cli_config.py", line 49, in command
    return func(*args, **kwargs)
           ^^^^^^^^^^^^^^^^^^^^^
  File "/home/airflow/.local/lib/python3.12/site-packages/airflow/utils/cli.py", line 115, in wrapper
    return f(*args, **kwargs)
           ^^^^^^^^^^^^^^^^^^
  File "/home/airflow/.local/lib/python3.12/site-packages/airflow/cli/commands/task_command.py", line 483, in task_run
    task_return_code = _run_task_by_selected_method(args, _dag, ti)
                       ^^^^^^^^^^^^^^^^^^^^^^^^^^^^^^^^^^^^^^^^^^^^
  File "/home/airflow/.local/lib/python3.12/site-packages/airflow/cli/commands/task_command.py", line 256, in _run_task_by_selected_method
    return _run_raw_task(args, ti)
           ^^^^^^^^^^^^^^^^^^^^^^^
  File "/home/airflow/.local/lib/python3.12/site-packages/airflow/cli/commands/task_command.py", line 341, in _run_raw_task
    return ti._run_raw_task(
           ^^^^^^^^^^^^^^^^^
  File "/home/airflow/.local/lib/python3.12/site-packages/airflow/utils/session.py", line 97, in wrapper
    return func(*args, session=session, **kwargs)
           ^^^^^^^^^^^^^^^^^^^^^^^^^^^^^^^^^^^^^^
  File "/home/airflow/.local/lib/python3.12/site-packages/airflow/models/taskinstance.py", line 3004, in _run_raw_task
    return _run_raw_task(
           ^^^^^^^^^^^^^^
  File "/home/airflow/.local/lib/python3.12/site-packages/airflow/models/taskinstance.py", line 365, in _run_raw_task
    TaskInstance.save_to_db(ti=ti, session=session)
  File "/home/airflow/.local/lib/python3.12/site-packages/airflow/api_internal/internal_api_call.py", line 139, in wrapper
    return func(*args, **kwargs)
           ^^^^^^^^^^^^^^^^^^^^^
  File "/home/airflow/.local/lib/python3.12/site-packages/airflow/utils/session.py", line 94, in wrapper
    return func(*args, **kwargs)
           ^^^^^^^^^^^^^^^^^^^^^
  File "/home/airflow/.local/lib/python3.12/site-packages/airflow/models/taskinstance.py", line 3399, in save_to_db
    session.flush()
  File "/home/airflow/.local/lib/python3.12/site-packages/sqlalchemy/orm/session.py", line 3449, in flush
    self._flush(objects)
  File "/home/airflow/.local/lib/python3.12/site-packages/sqlalchemy/orm/session.py", line 3588, in _flush
    with util.safe_reraise():
  File "/home/airflow/.local/lib/python3.12/site-packages/sqlalchemy/util/langhelpers.py", line 70, in __exit__
    compat.raise_(
  File "/home/airflow/.local/lib/python3.12/site-packages/sqlalchemy/util/compat.py", line 211, in raise_
    raise exception
  File "/home/airflow/.local/lib/python3.12/site-packages/sqlalchemy/orm/session.py", line 3549, in _flush
    flush_context.execute()
  File "/home/airflow/.local/lib/python3.12/site-packages/sqlalchemy/orm/unitofwork.py", line 456, in execute
    rec.execute(self)
  File "/home/airflow/.local/lib/python3.12/site-packages/sqlalchemy/orm/unitofwork.py", line 630, in execute
    util.preloaded.orm_persistence.save_obj(
  File "/home/airflow/.local/lib/python3.12/site-packages/sqlalchemy/orm/persistence.py", line 245, in save_obj
    _emit_insert_statements(
  File "/home/airflow/.local/lib/python3.12/site-packages/sqlalchemy/orm/persistence.py", line 1097, in _emit_insert_statements
    c = connection._execute_20(
        ^^^^^^^^^^^^^^^^^^^^^^^
  File "/home/airflow/.local/lib/python3.12/site-packages/sqlalchemy/engine/base.py", line 1710, in _execute_20
    return meth(self, args_10style, kwargs_10style, execution_options)
           ^^^^^^^^^^^^^^^^^^^^^^^^^^^^^^^^^^^^^^^^^^^^^^^^^^^^^^^^^^^
  File "/home/airflow/.local/lib/python3.12/site-packages/sqlalchemy/sql/elements.py", line 334, in _execute_on_connection
    return connection._execute_clauseelement(
           ^^^^^^^^^^^^^^^^^^^^^^^^^^^^^^^^^^
  File "/home/airflow/.local/lib/python3.12/site-packages/sqlalchemy/engine/base.py", line 1577, in _execute_clauseelement
    ret = self._execute_context(
          ^^^^^^^^^^^^^^^^^^^^^^
  File "/home/airflow/.local/lib/python3.12/site-packages/sqlalchemy/engine/base.py", line 1953, in _execute_context
    self._handle_dbapi_exception(
  File "/home/airflow/.local/lib/python3.12/site-packages/sqlalchemy/engine/base.py", line 2134, in _handle_dbapi_exception
    util.raise_(
  File "/home/airflow/.local/lib/python3.12/site-packages/sqlalchemy/util/compat.py", line 211, in raise_
    raise exception
  File "/home/airflow/.local/lib/python3.12/site-packages/sqlalchemy/engine/base.py", line 1910, in _execute_context
    self.dialect.do_execute(
  File "/home/airflow/.local/lib/python3.12/site-packages/sqlalchemy/engine/default.py", line 736, in do_execute
    cursor.execute(statement, parameters)
sqlalchemy.exc.IntegrityError: (psycopg2.errors.UniqueViolation) duplicate key value violates unique constraint "dag_run_dag_id_execution_date_key"
DETAIL:  Key (dag_id, execution_date)=(BuildELT_dbt, 2025-04-30 00:00:00+00) already exists.

[SQL: INSERT INTO dag_run (id, dag_id, queued_at, execution_date, start_date, end_date, state, run_id, creating_job_id, external_trigger, run_type, conf, data_interval_start, data_interval_end, last_scheduling_decision, dag_hash, log_template_id, updated_at, clear_number) VALUES (%(id)s, %(dag_id)s, %(queued_at)s, %(execution_date)s, %(start_date)s, %(end_date)s, %(state)s, %(run_id)s, %(creating_job_id)s, %(external_trigger)s, %(run_type)s, %(conf)s, %(data_interval_start)s, %(data_interval_end)s, %(last_scheduling_decision)s, %(dag_hash)s, %(log_template_id)s, %(updated_at)s, %(clear_number)s)]
[parameters: {'id': 52, 'dag_id': 'BuildELT_dbt', 'queued_at': datetime.datetime(2025, 5, 1, 7, 34, 51, 173886, tzinfo=Timezone('UTC')), 'execution_date': datetime.datetime(2025, 4, 30, 0, 0, tzinfo=Timezone('UTC')), 'start_date': datetime.datetime(2025, 5, 1, 7, 34, 51, 899713, tzinfo=Timezone('UTC')), 'end_date': None, 'state': 'running', 'run_id': 'manual__2025-04-30T00:00:00+00:00', 'creating_job_id': None, 'external_trigger': False, 'run_type': 'manual', 'conf': <psycopg2.extensions.Binary object at 0xffff97ec5ce0>, 'data_interval_start': datetime.datetime(2025, 4, 30, 0, 0, tzinfo=Timezone('UTC')), 'data_interval_end': datetime.datetime(2025, 4, 30, 0, 0, tzinfo=Timezone('UTC')), 'last_scheduling_decision': datetime.datetime(2025, 5, 1, 7, 34, 51, 939840, tzinfo=Timezone('UTC')), 'dag_hash': '5de38bd7dad17b8a325bb073f9b82c0c', 'log_template_id': 2, 'updated_at': datetime.datetime(2025, 5, 1, 7, 34, 51, 941816, tzinfo=Timezone('UTC')), 'clear_number': 1}]
(Background on this error at: https://sqlalche.me/e/14/gkpj)
[2025-05-01T07:35:07.927+0000] {local_task_job_runner.py:266} INFO - Task exited with return code 1
[2025-05-01T07:35:07.948+0000] {taskinstance.py:3900} INFO - 0 downstream tasks scheduled from follow-on schedule check
[2025-05-01T07:35:07.949+0000] {local_task_job_runner.py:245} INFO - ::endgroup::
